Workbook

Sheet Lisez-moi
A1: CAXE — Thèmes et chiffres des 4 agents
A2: Version 11 du 20 octobre 2026 : la version post-audit du 14 octobre, mise à jour d'après la banque de questions validée le 20 octobre.
A4: Ce qui a changé le 20 octobre
A5: Pourquoi | B5: La banque de questions des 4 agents a été validée le 20 octobre. Claude Code n'a pu y brancher que 385 questions sur 519 : les 134 autres portaient sur des données absentes du classeur ou marquées « Importées ». Cette version met le classeur à jour sur tout ce que la banque a changé, pas seulement ces 134 lignes.
A6: En chiffres | B6: 19 thèmes ajoutés, 103 données ajoutées, 31 données importées passées en demandées, 13 données qui ne sont plus posées (lues dans une autre réponse), 48 conditions d'affichage, 23 niveaux, 38 profils, 38 déclencheurs ajoutés (D28 à D65), le profil Location et les lexiques par métier.
A7: Où le voir | B7: Onglet « Modifications 20 oct. » : une ligne par changement, avec l'avant et l'après. Dans les autres onglets, le code est vert sur une ligne nouvelle et violet sur une ligne modifiée ; la dernière colonne dit ce qui a changé.
A8: À valider | B8: La nature de notation et l'impact des 19 thèmes nouveaux sont des propositions : la banque ne les dit pas. Leur liste est en tête de l'onglet « Modifications 20 oct. ».
A10: Provenance de ce fichier
A11: Source | B11: Les fichiers data/*.json du dépôt calixtecaxe-hue/Test (importés le 15 octobre depuis CAXE_Themes_Chiffres_4_agents_8.xlsx, la version post-audit), puis la page « Banque de questions CAXE » validée le 20 octobre.
A12: Contrôle | B12: Ce classeur se réimporte avec scripts/importer-classeur.py. Les colonnes « Location » et « Clé dans les questions » ne sont pas encore lues par ce script : Claude Code doit les brancher (voir l'onglet Modifications).
A13: Différences avec l'original | B13: La colonne « Chiffres à demander » de l'onglet Thèmes liste les codes demandés ou partagés de chaque thème ; l'onglet Synthèse est en formules.
A15: Utilisation avec le moteur
A16: Règle | B16: Le classeur reste l'outil d'écriture. On le modifie, puis on relance l'import : on ne modifie jamais les JSON à la main.
A17: Commandes | B17: python3 scripts/importer-classeur.py CAXE_Themes_Chiffres_4_agents.xlsx, puis npm run donnees:controle.
A18: À ne pas faire | B18: Renommer un onglet, déplacer une colonne ou insérer une ligne au-dessus des en-têtes : l'import lit les colonnes par position.
A20: Légende
A21: Marché | B21: Le chiffre du client comparé à une référence de marché sourcée. La moyenne du marché est orange, le vert est au-dessus.
A22: Pratique | B22: Une bonne pratique reconnue est-elle en place : absente, partielle ou en place.
A23: Cohérence | B23: Les réponses du client comparées entre elles.
A24: Contexte | B24: Non noté. Sert seulement à l'IA pour expliquer le diagnostic.
A25: Impact | B25: Chiffré (CA, trésorerie, contacts, marge ou heures) quand le thème est sur une vraie chaîne de calcul ; sinon Qualifié (Bloquant, Frein, Secondaire).
A26: Mode d'une donnée | B26: Demandée : posée au dirigeant. Partagée : posée une seule fois, par le premier agent souscrit qui en a besoin. Importée : lue dans un outil connecté. Calculée : déduite d'autres données. Autre agent : reprise d'un autre agent.
A27: Niveau | B27: Essentiel : audit initial. Approfondi : posé dans un second temps. Les données calculées n'ont pas de niveau.
A28: Condition d'affichage | B28: La question déclencheuse (D01 à D65, onglet Déclencheurs) dont dépend la donnée. Une case orange signale une donnée qui n'est pas posée à tout le monde. « D26 + D63 » : les deux conditions sont nécessaires.
A29: Profils | B29: RDV = rendez-vous · Commerce · E-commerce · Restaurant · Chantier = artisan ou chantier · B2B = cycle long · Abonnement · Location = hébergement et location de véhicules. Un ● signifie que la donnée est posée à ce profil.
A30: Couleur du code | B30: Vert : ligne nouvelle le 20 octobre. Violet : ligne modifiée le 20 octobre (le détail est dans la dernière colonne).
A31: Tailles (onglets RH) | B31: L'agent RH se règle sur la taille de l'entreprise : Seul · 2 à 5 · 6 et +.
A32: Nom du thème | B32: Colonne C des onglets de données : formule qui reprend le nom depuis l'onglet Thèmes.

Sheet Modifications 20 oct.
A1: Modifications du 20 octobre 2026
A2: Le classeur mis à jour d'après la banque de questions validée le 20 octobre. Trois parties : ce que tu dois valider, ce que Claude Code doit faire après l'import, puis chaque modification avec l'avant et l'après.
A4: 1. À valider par toi : nature de notation et impact des 19 thèmes nouveaux (propositions)
A5: Thème | B5: Nature | C5: Impact | D5: Bloc | E5: Pourquoi
A6: FIN-46 Rémunération du dirigeant | B6: Cohérence | C6: Qualifié | D6: Marges et rentabilité | E6: Ce que le dirigeant se verse, ses cotisations et ce qu'il souhaite se lisent entre eux.
A7: FIN-47 Cadre de l'activité | B7: Contexte | C7: — | D7: Pilotage | E7: Forme de l'entreprise : sert seulement à lire les chiffres (D31). Rien à noter.
A8: FIN-48 Relation avec la banque | B8: Pratique | C8: Qualifié | D8: Financement | E8: Bonne pratique : faire le point avec son banquier. Une seule question : le contrôle le signalera.
A9: RH-41 Projet d'équipe | B9: Contexte | C9: — | D9: S'entourer (dirigeant seul) | E9: Projet de se faire aider : décrit une intention. Rien à noter.
A10: RH-42 Tâches à confier | B10: Contexte | C10: — | D10: S'entourer (dirigeant seul) | E10: Tâches à confier : nourrit le plan d'action. Rien à noter.
A11: RH-43 Moyens pour une première aide | B11: Cohérence | C11: Qualifié | D11: S'entourer (dirigeant seul) | E11: Budget envisagé face aux demandes perdues et aux heures à confier : les réponses se lisent entre elles.
A12: RH-44 Freins | B12: Contexte | C12: — | D12: S'entourer (dirigeant seul) | E12: Ce qui retient de se faire aider : contexte pour l'IA.
A13: RH-45 Relais quand on est seul | B13: Pratique | C13: Qualifié | D13: S'entourer (dirigeant seul) | E13: Relais auprès des clients, informations notées, réseau : pratique absente, partielle ou en place.
A14: RH-46 Composition de l'équipe | B14: Contexte | C14: — | D14: Rôles et délégation | E14: Qui fait quoi dans l'équipe : décrit, ne se note pas. Partagée avec ACQ-21.01.
A15: RH-47 Planning de l'équipe | B15: Pratique | C15: Qualifié | D15: Charge et planification | E15: Qui fait le planning, délai de prévenance, changements de dernière minute : pratique.
A16: RH-48 Objectifs individuels | B16: Pratique | C16: Qualifié | D16: Management | E16: Objectifs écrits et revus, part variable : pratique.
... A24: COM-61 Funnel 7 · Relancer les intéressés | B24: Pratique | C24: Qualifié | D24: De la publication au contact | E24: Relance des personnes intéressées : pratique ; le taux de transformation vient de COM-61.02.
A26: 2. À faire par Claude Code après l'import
A27: 1. Importer | B27: python3 scripts/importer-classeur.py CAXE_Themes_Chiffres_4_agents_11.xlsx
A28: 2. Brancher deux colonnes | B28: Dans scripts/importer-classeur.py, AVANT l'import : lire la colonne « Clé dans les questions » de l'onglet Lexique (écrire « cle » quand elle diffère de cle_lexique(mot)). Sans elle, 8 mots ({demandes}, {unites_vendues}, {unites_a_louer}, {jours_ouverture}, {hors_location}, {devis_pluriel}, {ventes_realisees}, {exemples_travail}) perdent leur clé et les questions qui les emploient ne s'affichent plus. Avec cette lecture, data/lexique.json ressort identique. Ensuite : la colonne « Location » des onglets de données (8e profil) et les lexiques par métier.
A29: 3. Profil location | B29: Ajouter le profil location au code (constantes, routage des métiers d'hébergement et de location de véhicules, lexique) et une colonne Location dans les onglets Croisements.
A30: 4. Règles d'affichage | B30: data/regles-affichage.json : une règle pour chacune des 42 conditions qui n'en ont pas encore, plus le masquage « Au moins un salarié » (liste exacte : npm run donnees:controle après l'import ; ce sont ses 43 seules erreurs une fois les points 2, 5 et 6 faits), dont « D26 + D63 » (les deux nécessaires) et « Pas posée si les agents Acquisition et Comm sont faits : calculée » (FIN-05.02). D21 devient un choix à trois réponses (« Oui, au moins une fois par mois » = parcours amélioration). D03 passe à 17 canaux. Masquage nouveau « Au moins un salarié » (D02 différent de « seul ») pour les thèmes RH-41 à RH-45.
A31: 5. Catalogue des thèmes | B31: Fiches des 19 thèmes nouveaux dans data/catalogue-themes.json (python3 scripts/ecrire-catalogue-themes.py).
A32: 6. Limite de texte | B32: COM-44.04 (les 20 derniers avis, copiés-collés) accepte 8 000 caractères dans la banque ; src/lib/donnees/reponse-spec.ts plafonne un texte à 2 000. Monter ce plafond à 8 000, sinon le contrôle refuse data/banque/questions.json.
A33: 7. Questions en attente | B33: Relancer python3 scripts/importer-banque.py <page de la banque> --ecarter-inconnues : data/banque/en-attente.json disparaît, les 519 questions sont posables (vérifié le 20 octobre sur une copie du dépôt : 519 écrites, 0 manquante). Puis npm run donnees:controle.
A34: 8. Tests à mettre à jour | B34: Comptes écrits en dur dans tests/donnees.test.mts : thèmes par agent 23 / 48 / 49 / 61 (au lieu de 23 / 45 / 40 / 54), 11 thèmes de nature Contexte (au lieu de 4), 65 déclencheurs (au lieu de 27). Les autres tests en échec tombent avec les règles d'affichage (point 4) et le profil location (point 3 : ACQ-11.31 à 11.37 ne sont posées à aucun des 7 profils).
A35: 9. Calculs à écrire | B35: Annoncés par la banque, pas encore dans le classeur (rien n'est inventé ici) : ACQ-11.38 taux d'occupation, ACQ-11.39 prix moyen d'une unité vendue, ACQ-11.40 CA perdu par mois et un croisement location en miroir de XA34 (formules dans l'onglet Modifications de la banque, point D1) ; couverts par mois = ACQ-11.07 × ACQ-11.09 × 4,33 ; nombres par canal = ACQ-02.01 × ACQ-03.02 et ACQ-11.01 × ACQ-03.03, repris par ACQ-03.07, 03.08, 03.09, 03.10, 03.12, 06.09, 18.04, COM-12.01, COM-19.03 et COM-22.02 ; calculs du funnel Comm (COM-58.03, COM-61.03, COM-39.06) ; formules et croisements des 19 thèmes nouveaux.
A37: 3. Toutes les modifications (438 lignes)
A38: Catégorie | B38: Code | C38: Ce qui change | D38: Avant | E38: Après
A39: Thème ajouté | B39: COM-55 | C39: Thème nouveau (nature et impact proposés, à valider) | D39: — | E39: Funnel 3 · Visiter le profil : ce qu'il contient · bloc « De la publication au contact » · Pratique · impact Qualifié · masqué pour « Ne publie pas (parcours mise en place) »
A40: Thème ajouté | B40: COM-56 | C40: Thème nouveau (nature et impact proposés, à valider) | D40: — | E40: Démarrage · bloc « Présence et canaux » · Contexte · impact —
A41: Thème ajouté | B41: COM-57 | C41: Thème nouveau (nature et impact proposés, à valider) | D41: — | E41: Brief de création · bloc « Production » · Contexte · impact —
A42: Thème ajouté | B42: COM-58 | C42: Thème nouveau (nature et impact proposés, à valider) | D42: — | E42: Funnel 0 · Le chemin prévu · bloc « De la publication au contact » · Pratique · impact Qualifié
A43: Thème ajouté | B43: COM-59 | C43: Thème nouveau (nature et impact proposés, à valider) | D43: — | E43: Funnel 3 · Visiter le profil · bloc « De la publication au contact » · Cohérence · impact Chiffré (contacts) · masqué pour « Ne publie pas (parcours mise en place) »
A44: Thème ajouté | B44: COM-60 | C44: Thème nouveau (nature et impact proposés, à valider) | D44: — | E44: Funnel 5 · Arriver au bon endroit · bloc « De la publication au contact » · Pratique · impact Qualifié · masqué pour « Ne publie pas (parcours mise en place) »
A45: Thème ajouté | B45: COM-61 | C45: Thème nouveau (nature et impact proposés, à valider) | D45: — | E45: Funnel 7 · Relancer les intéressés · bloc « De la publication au contact » · Pratique · impact Qualifié · masqué pour « Ne publie pas (parcours mise en place) »
A46: Thème ajouté | B46: FIN-46 | C46: Thème nouveau (nature et impact proposés, à valider) | D46: — | E46: Rémunération du dirigeant · bloc « Marges et rentabilité » · Cohérence · impact Qualifié
A47: Thème ajouté | B47: FIN-47 | C47: Thème nouveau (nature et impact proposés, à valider) | D47: — | E47: Cadre de l'activité · bloc « Pilotage » · Contexte · impact —
A48: Thème ajouté | B48: FIN-48 | C48: Thème nouveau (nature et impact proposés, à valider) | D48: — | E48: Relation avec la banque · bloc « Financement » · Pratique · impact Qualifié
A49: Thème ajouté | B49: RH-41 | C49: Thème nouveau (nature et impact proposés, à valider) | D49: — | E49: Projet d'équipe · bloc « S'entourer (dirigeant seul) » · Contexte · impact — · masqué pour « Au moins un salarié »
... A476: Déclencheur | B476: D26 | C476: Déclencheur : effet | D476: Connecté : statistiques des 10 dernières publications lues automatiquement. Accès manuel : saisie des 3 meilleures et 3 moins bonnes. Non : estimations en tranches | E476: Oui : saisie des statistiques des 3 meilleures et 3 moins bonnes publications ; lecture automatique quand la connexion existera. Non : estimations.

Sheet Modifications 28 oct.
A1: Code | B1: Champ | C1: Avant | D1: Après | E1: Pourquoi
A2: ACQ-02.02 | B2: periode | C2: Si plus de 6 mois d'existence (sinon masquée) | D2: 3 mois, 6 mois plus tôt (masquée avant 9 mois d'existence) | E2: Comparée à la moyenne des 3 derniers mois (ACQ-02.01) : mêmes 3 mois de longueur, 6 mois plus tôt. Avant 9 mois, ces mois précèdent la création.
A3: ACQ-02.03 | B3: periode | C3: Si plus de 12 mois d'existence (sinon masquée) | D3: Mêmes 3 mois, un an plus tôt (masquée avant 15 mois d'existence) | E3: « Il y a un an, à la même période » ne disait pas quels mois : ce sont les mêmes 3 mois qu'ACQ-02.01, un an plus tôt. Avant 15 mois, ils précèdent la création.
A4: ACQ-11.02 | B4: periode | C4: Si plus de 12 mois d'existence (sinon masquée) | D4: Mêmes 3 mois, un an plus tôt (masquée avant 15 mois d'existence) | E4: Comme ACQ-02.03, pour les nouveaux clients (comparée à ACQ-11.01).
A5: ACQ-03.06 | B5: periode | C5: Période adaptée : depuis la création si moins de 12 mois | D5: 12 mois précédents (masquée avant 24 mois d'existence) | E5: Compare les 12 derniers mois aux 12 mois précédents : il faut 24 mois d'existence. « Période adaptée » posait la question à une entreprise de 13 mois.
A6: ACQ-06.07 | B6: periode | C6: — | D6: Période adaptée : depuis la création si moins de 3 mois | E6: Période déjà écrite dans la question (moyenne des 3 derniers mois) ; nécessaire pour la comparer à COM-13.06.
A7: ACQ-07.05 | B7: periode | C7: Si plus de 12 mois d'existence (sinon masquée) | D7: Il y a 12 mois (masquée avant 12 mois d'existence) | E7: Même masquage ; le mois comparé est maintenant précisé.
A8: ACQ-03.05 | B8: periode | C8: — | D8: Aujourd'hui | E8: Montant par mois actuel, comparé au budget d'il y a 12 mois (ACQ-07.05).
A9: ACQ-07.01 | B9: periode | C9: — | D9: Aujourd'hui | E9: Montant par mois actuel, comparé au budget d'il y a 12 mois (ACQ-07.05).
A10: ACQ-07.03 | B10: periode | C10: — | D10: Aujourd'hui | E10: Montant par mois actuel, comparé au budget d'il y a 12 mois (ACQ-07.05).
A11: ACQ-07.04 | B11: periode | C11: — | D11: Aujourd'hui | E11: Montant par mois actuel, comparé au budget d'il y a 12 mois (ACQ-07.05).
A12: ACQ-16.03 | B12: periode | C12: Période adaptée : depuis la création si moins de 12 mois | D12: 12 mois précédents (masquée avant 24 mois d'existence) | E12: « L'année d'avant » est comparée aux 12 derniers mois (ACQ-16.01) : il faut 24 mois. « Période adaptée » la posait dès la création.
... A55: FIN-37.06 | B55: entrees | C55: FIN-37.01, FIN-37.02, ACQ-23.01 | D55: FIN-37.01, FIN-37.02, ACQ-23.10 | E55: Entrées du calcul réécrit.
A56: ACQ-23.13 | B56: nouvelle donnée | D56: Changement de périmètre de l'activité sur les 24 derniers mois (ouverture ou fermeture d'un établissement, rachat ou vente, nouvelle activité ou arrêt) et mois du changement — partagée avec FIN-14.04 | E56: Une évolution d'une année sur l'autre n'a pas de sens si l'activité n'a pas le même périmètre : ouverture d'un second site, rachat, arrêt d'une activité.
A57: ACQ-23.12 | B57: nouvelle donnée | D57: Nombre de ventes sur les 12 mois précédents (pour comparer le montant moyen d'une vente d'une année sur l'autre) | E57: L'évolution du panier (ACQ-15.07) compare deux années ; le nombre de ventes de l'année précédente n'était demandé nulle part.
A58: FIN-07.17 | B58: nouvelle donnée | D58: Nombre de personnes dans l'entreprise il y a 12 mois, vous compris (même définition que le dossier d'entreprise) | E58: Une masse salariale qui augmente n'a pas le même sens si l'équipe a grandi : l'effectif d'il y a 12 mois n'était demandé nulle part (le dossier ne donne que l'effectif actuel).
A59: FIN-14.04 | B59: nouvelle donnée | D59: Changement de périmètre de l'activité sur les 24 derniers mois, et mois du changement | E59: Partage avec la Finance de la question sur le périmètre.
A60: FIN-14.03 | B60: nouvelle donnée | D60: CA des mêmes mois l'année précédente | E60: La Finance compare son chiffre d'affaires d'une année sur l'autre (XF07, FIN-04, FIN-07.15, FIN-37.06) sans que ce chiffre lui soit demandé.

Sheet Synthèse
A1: Synthèse par agent
A2: Tous les chiffres sont des formules sur les onglets Thèmes, données et croisements.
A4: Agent | B4: Thèmes | C4: Marché | D4: Pratique | E4: Cohérence | F4: Contexte | G4: Impact chiffré | H4: Impact qualifié | I4: Données | J4: Demandées | K4: Partagées | L4: Importées | M4: Calculées | N4: Autre agent | O4: Essentielles | P4: Approfondies | Q4: Croisements | R4: Scénarios
A5: Acquisition & CA | B5: =COUNTIF(Thèmes!$B:$B,$A5) | C5: =COUNTIFS(Thèmes!$B:$B,$A5,Thèmes!$E:$E,"Marché") | D5: =COUNTIFS(Thèmes!$B:$B,$A5,Thèmes!$E:$E,"Pratique") | E5: =COUNTIFS(Thèmes!$B:$B,$A5,Thèmes!$E:$E,"Cohérence") | F5: =COUNTIFS(Thèmes!$B:$B,$A5,Thèmes!$E:$E,"Contexte") | G5: =COUNTIFS(Thèmes!$B:$B,$A5,Thèmes!$F:$F,"Chiffré*") | H5: =COUNTIFS(Thèmes!$B:$B,$A5,Thèmes!$F:$F,"Qualifié") | I5: =COUNTA('Acquisition — données'!$A:$A)-1 | J5: =COUNTIF('Acquisition — données'!$G:$G,"Demandée") | K5: =COUNTIF('Acquisition — données'!$G:$G,"Partagée") | L5: =COUNTIF('Acquisition — données'!$G:$G,"Importée") | M5: =COUNTIF('Acquisition — données'!$G:$G,"Calculée") | N5: =COUNTIF('Acquisition — données'!$G:$G,"Autre agent") | O5: =COUNTIF('Acquisition — données'!$H:$H,"Essentiel") | P5: =COUNTIF('Acquisition — données'!$H:$H,"Approfondi") | Q5: =COUNTIF(Croisements!$B:$B,$A5) | R5: 0
A6: Finance & Rentabilité | B6: =COUNTIF(Thèmes!$B:$B,$A6) | C6: =COUNTIFS(Thèmes!$B:$B,$A6,Thèmes!$E:$E,"Marché") | D6: =COUNTIFS(Thèmes!$B:$B,$A6,Thèmes!$E:$E,"Pratique") | E6: =COUNTIFS(Thèmes!$B:$B,$A6,Thèmes!$E:$E,"Cohérence") | F6: =COUNTIFS(Thèmes!$B:$B,$A6,Thèmes!$E:$E,"Contexte") | G6: =COUNTIFS(Thèmes!$B:$B,$A6,Thèmes!$F:$F,"Chiffré*") | H6: =COUNTIFS(Thèmes!$B:$B,$A6,Thèmes!$F:$F,"Qualifié") | I6: =COUNTA('Finance — données'!$A:$A)-1 | J6: =COUNTIF('Finance — données'!$G:$G,"Demandée") | K6: =COUNTIF('Finance — données'!$G:$G,"Partagée") | L6: =COUNTIF('Finance — données'!$G:$G,"Importée") | M6: =COUNTIF('Finance — données'!$G:$G,"Calculée") | N6: =COUNTIF('Finance — données'!$G:$G,"Autre agent") | O6: =COUNTIF('Finance — données'!$H:$H,"Essentiel") | P6: =COUNTIF('Finance — données'!$H:$H,"Approfondi") | Q6: =COUNTIF(Croisements!$B:$B,$A6) | R6: =COUNTA(Scénarios!$A$5:$A$200)
A7: RH & Organisation | B7: =COUNTIF(Thèmes!$B:$B,$A7) | C7: =COUNTIFS(Thèmes!$B:$B,$A7,Thèmes!$E:$E,"Marché") | D7: =COUNTIFS(Thèmes!$B:$B,$A7,Thèmes!$E:$E,"Pratique") | E7: =COUNTIFS(Thèmes!$B:$B,$A7,Thèmes!$E:$E,"Cohérence") | F7: =COUNTIFS(Thèmes!$B:$B,$A7,Thèmes!$E:$E,"Contexte") | G7: =COUNTIFS(Thèmes!$B:$B,$A7,Thèmes!$F:$F,"Chiffré*") | H7: =COUNTIFS(Thèmes!$B:$B,$A7,Thèmes!$F:$F,"Qualifié") | I7: =COUNTA('RH — données'!$A:$A)-1 | J7: =COUNTIF('RH — données'!$G:$G,"Demandée") | K7: =COUNTIF('RH — données'!$G:$G,"Partagée") | L7: =COUNTIF('RH — données'!$G:$G,"Importée") | M7: =COUNTIF('RH — données'!$G:$G,"Calculée") | N7: =COUNTIF('RH — données'!$G:$G,"Autre agent") | O7: =COUNTIF('RH — données'!$H:$H,"Essentiel") | P7: =COUNTIF('RH — données'!$H:$H,"Approfondi") | Q7: =COUNTIF('Croisements RH'!$B:$B,$A7) | R7: 0
A8: Comm & Création | B8: =COUNTIF(Thèmes!$B:$B,$A8) | C8: =COUNTIFS(Thèmes!$B:$B,$A8,Thèmes!$E:$E,"Marché") | D8: =COUNTIFS(Thèmes!$B:$B,$A8,Thèmes!$E:$E,"Pratique") | E8: =COUNTIFS(Thèmes!$B:$B,$A8,Thèmes!$E:$E,"Cohérence") | F8: =COUNTIFS(Thèmes!$B:$B,$A8,Thèmes!$E:$E,"Contexte") | G8: =COUNTIFS(Thèmes!$B:$B,$A8,Thèmes!$F:$F,"Chiffré*") | H8: =COUNTIFS(Thèmes!$B:$B,$A8,Thèmes!$F:$F,"Qualifié") | I8: =COUNTA('Comm — données'!$A:$A)-1 | J8: =COUNTIF('Comm — données'!$G:$G,"Demandée") | K8: =COUNTIF('Comm — données'!$G:$G,"Partagée") | L8: =COUNTIF('Comm — données'!$G:$G,"Importée") | M8: =COUNTIF('Comm — données'!$G:$G,"Calculée") | N8: =COUNTIF('Comm — données'!$G:$G,"Autre agent") | O8: =COUNTIF('Comm — données'!$H:$H,"Essentiel") | P8: =COUNTIF('Comm — données'!$H:$H,"Approfondi") | Q8: =COUNTIF(Croisements!$B:$B,$A8) | R8: 0
A9: Total | B9: =SUM(B5:B8) | C9: =SUM(C5:C8) | D9: =SUM(D5:D8) | E9: =SUM(E5:E8) | F9: =SUM(F5:F8) | G9: =SUM(G5:G8) | H9: =SUM(H5:H8) | I9: =SUM(I5:I8) | ... R9: =SUM(R5:R8)
A11: Déclencheurs | B11: =COUNTA(Déclencheurs!$A$5:$A$200)
A12: Mots du lexique | B12: =COUNTA(Lexique!$A$5:$A$200)
A13: Problèmes du diagnostic Comm | B13: =COUNTIF('Diagnostic Comm'!$A$5:$A$200,"DC*")
A14: Les données partagées sont posées une seule fois, par le premier agent souscrit qui en a besoin : la colonne « Partagées » compte ces lignes une fois chacune.

Sheet Thèmes
A1: Code | B1: Agent | C1: Bloc / étape | D1: Thème | E1: Nature de notation | F1: Impact sur l'objectif | G1: Chiffre nécessaire | H1: Chiffres demandés (codes, d'après les onglets de données) | I1: Déjà connu ailleurs | J1: Comment le volume change la méthode | K1: Si le chiffre est inconnu | L1: Masqué pour | M1: Changement du 20 oct.
A2: ACQ-01 | B2: Acquisition & CA | C2: Attirer | D2: Cible | E2: Cohérence | F2: Qualifié | G2: Oui | H2: ACQ-01.01, ACQ-01.02, ACQ-01.03, ACQ-01.04, ACQ-01.05, ACQ-01.06, ACQ-01.07, ACQ-01.08, ACQ-01.09, ACQ-01.10 | I2: Métier et zone (inscription) | J2: 70 % du CA vient d'un type de client non ciblé → recentrer la cible sur lui. CA éparpillé sur 5 types → choisir un segment prioritaire. | K2: Classer ses types de clients du plus au moins rentable, sans chiffre. | L2: —
A3: ACQ-02 | B3: Acquisition & CA | C3: Attirer | D3: Volume de contacts | E3: Marché | F3: Chiffré (CA) | G3: Oui | H3: ACQ-02.01, ACQ-02.02, ACQ-02.03, ACQ-02.04, ACQ-02.05 | I3: Partagé avec COM-13 (posé une seule fois) | J3: Peu de contacts mais bonne transformation → travailler l'apport de contacts. Beaucoup de contacts mal transformés → travailler la conversion d'abord. | K3: Première action : compter les demandes pendant 4 semaines. | L3: —
A4: ACQ-03 | B4: Acquisition & CA | C4: Attirer | D4: Canaux | E4: Cohérence | F4: Chiffré (CA) | G4: Oui | H4: ACQ-03.01, ACQ-03.02, ACQ-03.03, ACQ-03.04, ACQ-03.05, ACQ-03.06 | I4: Partagé avec COM-12 (posé une seule fois) | J4: Un canal = 80 % des contacts → ouvrir un 2e canal. 5 canaux à 5 contacts chacun → concentrer l'effort sur le meilleur. | K4: Classer ses canaux du plus au moins efficace. | L4: —
A5: ACQ-04 | B5: Acquisition & CA | C5: Attirer | D5: Prospection active | E5: Pratique | F5: Chiffré (CA) | G5: Oui | H5: ACQ-04.01, ACQ-04.02, ACQ-04.03, ACQ-04.04, ACQ-04.05, ACQ-04.06 | I5: — | J5: Aucune action → installer une routine minimale. 50 appels pour 0 rendez-vous → revoir le message, pas le volume. | K5: Noter ses actions de prospection pendant 2 semaines. | L5: —
A6: ACQ-05 | B6: Acquisition & CA | C6: Attirer | D6: Partenaires | E6: Pratique | F6: Chiffré (CA) | G6: Oui | H6: ACQ-05.01, ACQ-05.02, ACQ-05.03, ACQ-05.04 | I6: — | J6: Aucun partenaire → identifier 3 prescripteurs naturels du métier. 10 partenaires dont un seul apporte → l'entretenir et réactiver les autres. | K6: Citer les partenaires qui ont apporté au moins un client cette année. | L6: —
A7: ACQ-06 | B7: Acquisition & CA | C7: Attirer | D7: Présence en ligne | E7: Pratique | F7: Qualifié | G7: Oui | H7: ACQ-06.01, ACQ-06.04, ACQ-06.06, ACQ-06.07, ACQ-06.08, ACQ-06.12, ACQ-06.13 | I7: Partagé avec COM-13, COM-14 et COM-44 (posé une seule fois) ; lu sur la fiche Google si connectée | J7: 5 avis → campagne de sollicitation. 200 avis à 4,8 → maintenir, le levier est ailleurs. Analyse du contenu → renvoi Comm. | K7: Lu directement sur la fiche Google. | L7: —
A8: ACQ-07 | B8: Acquisition & CA | C8: Attirer | D8: Budget et coût d'acquisition | E8: Cohérence | F8: Chiffré (CA) | G8: Oui | H8: ACQ-07.01, ACQ-07.02, ACQ-07.03, ACQ-07.04, ACQ-07.05, ACQ-07.15 | I8: Partagé avec FIN-05 et COM-32 (posé une seule fois) ; CA mensuel (inscription) ; clients signés (ACQ-11) | J8: Coût d'un client supérieur à son panier → couper le canal le plus cher. Budget nul et peu de clients → tester un petit budget sur le meilleur canal. | K8: Additionner les dépenses marketing des 3 derniers relevés bancaires. | L8: —
A9: ACQ-08 | B9: Acquisition & CA | C9: Convertir | D9: Réactivité | E9: Marché | F9: Chiffré (CA) | G9: Oui | H9: ACQ-08.01, ACQ-08.02, ACQ-08.03, ACQ-08.04, ACQ-08.05 | I9: Demandes par mois (ACQ-02) | J9: 5 demandes par mois → réponse personnelle dans l'heure. 100 par mois → accusé de réception automatique et créneau de rappel. | K9: Noter l'heure de réception et de réponse des 10 prochaines demandes. | L9: —
A10: ACQ-09 | B10: Acquisition & CA | C10: Convertir | D10: Rendez-vous | E10: Marché | F10: Chiffré (CA) | G10: Oui | H10: ACQ-09.01, ACQ-09.02, ACQ-09.05, ACQ-09.06, ACQ-09.07 | I10: Demandes par mois (ACQ-02) | J10: Absences fréquentes sur gros volume → rappel automatique la veille. Petit volume → appel de confirmation personnel. | K10: Compter les rendez-vous du mois dernier dans l'agenda. | L10: Métiers sans rendez-vous
A11: ACQ-10 | B11: Acquisition & CA | C11: Convertir | D11: Devis et relances | E11: Marché | F11: Chiffré (CA) | G11: Oui | H11: ACQ-10.01, ACQ-10.03, ACQ-10.05, ACQ-10.06, ACQ-10.07, ACQ-10.08, ACQ-10.09, ACQ-10.10, ACQ-10.11 | I11: — | J11: 5 devis par mois → relance à la main sous 3 jours. 150 par mois → séquence de relance automatique. | K11: Compter les devis du dernier mois dans le logiciel ou la boîte mail. | L11: Métiers sans devis
A12: ACQ-11 | B12: Acquisition & CA | C12: Convertir | D12: Transformation | E12: Marché | F12: Chiffré (CA) | G12: Oui | H12: ACQ-11.01, ACQ-11.02, ACQ-11.03, ACQ-11.04, ACQ-11.05, ACQ-11.07, ACQ-11.08, ACQ-11.09, ACQ-11.10, ACQ-11.11, ACQ-11.12, ACQ-11.13, ACQ-11.15, ACQ-11.16, ACQ-11.17, ACQ-11.31, ACQ-11.32, ACQ-11.33, ACQ-11.34, ACQ-11.35, ACQ-11.36, ACQ-11.37, ACQ-11.38, ACQ-11.39 | I12: Partagé avec FIN-06 (posé une seule fois) ; Rendez-vous (ACQ-09) | J12: Peu de rendez-vous mal transformés → mieux préparer chaque rendez-vous. Beaucoup de rendez-vous mal transformés → mieux qualifier avant le rendez-vous. | K12: Compter les clients signés le mois dernier. | L12: —
A13: ACQ-12 | B13: Acquisition & CA | C13: Convertir | D13: Durée du cycle de vente | E13: Marché | F13: Chiffré (CA) | G13: Oui | H13: ACQ-12.01, ACQ-12.02, ACQ-12.03, ACQ-12.04 | I13: — | J13: Cycle long sur peu de dossiers → suivi individuel de chaque dossier. Cycle long sur gros volume → étapes et relances standardisées. | K13: Prendre les 5 dernières ventes et noter leurs deux dates. | L13: Vente immédiate (commerce)
... A24: ACQ-23 | B24: Acquisition & CA | C24: Piloter | D24: Saisonnalité | E24: Cohérence | F24: Chiffré (CA) | G24: Oui | H24: ACQ-23.01, ACQ-23.02, ACQ-23.03, ACQ-23.04, ACQ-23.12, ACQ-23.13 | I24: Partagé avec FIN-14 et RH-11 (posé une seule fois) | J24: Écart faible → pas d'action. Creux de 50 % → lancer la prospection 2 mois avant le creux. | K24: Citer les mois forts et faibles, sans chiffre. | L24: —
A25: ACQ-24 | B25: Acquisition & CA | C25: Piloter | D25: Objectif et moyens | E25: Contexte | F25: — | G25: Non | H25: ACQ-24.02 | I25: — | J25: — | K25: — | L25: — | M25: Nouveau : nature, impact et étape proposés, à valider
A26: ACQ-25 | B26: Acquisition & CA | C26: Votre métier | D26: Métier · Transport de personnes et coursiers | E26: Contexte | F26: — | G26: Non | H26: ACQ-25.01, ACQ-25.02, ACQ-25.03, ACQ-25.04 | I26: — | J26: — | K26: — | L26: — | M26: Nouveau : module métier ; nature, impact et étape proposés, à valider
A27: ACQ-27 | B27: Acquisition & CA | C27: Votre métier | D27: Métier · Négoce | E27: Contexte | F27: — | G27: Non | H27: ACQ-27.01, ACQ-27.02, ACQ-27.03, ACQ-27.04 | I27: — | J27: — | K27: — | L27: — | M27: Nouveau : module métier ; nature, impact et étape proposés, à valider
A28: ACQ-28 | B28: Acquisition & CA | C28: Votre métier | D28: Métier · Vente de véhicules et de logements | E28: Contexte | F28: — | G28: Non | H28: ACQ-28.01, ACQ-28.02, ACQ-28.03, ACQ-28.04 | I28: — | J28: — | K28: — | L28: — | M28: Nouveau : module métier ; nature, impact et étape proposés, à valider
A29: ACQ-29 | B29: Acquisition & CA | C29: Votre métier | D29: Métier · Immobilier | E29: Contexte | F29: — | G29: Non | H29: ACQ-29.01, ACQ-29.02, ACQ-29.03, ACQ-29.04 | I29: — | J29: — | K29: — | L29: — | M29: Nouveau : module métier ; nature, impact et étape proposés, à valider
A30: ACQ-30 | B30: Acquisition & CA | C30: Piloter | D30: Contexte | E30: Contexte | F30: — | G30: Non | H30: ACQ-30.01 | I30: — | J30: — | K30: — | L30: — | M30: Nouveau : nature, impact et étape proposés, à valider
A31: FIN-01 | B31: Finance & Rentabilité | C31: Marges et rentabilité | D31: Marge par offre | E31: Cohérence | F31: Chiffré (marge) | G31: Oui | H31: FIN-01.01, FIN-01.02, FIN-01.03 | I31: Partagé avec ACQ-13 (posé une seule fois) | J31: L'offre la moins rentable fait 50 % du CA → revoir son prix. Elle fait 5 % du CA → envisager de l'arrêter. | K31: Classer ses offres de la plus à la moins rentable, sans chiffre. | L31: —
A32: FIN-02 | B32: Finance & Rentabilité | C32: Marges et rentabilité | D32: Marge par client | E32: Cohérence | F32: Chiffré (marge) | G32: Oui | H32: FIN-02.01 | I32: Répartition du CA (ACQ-16) | J32: 1 client non rentable sur 50 → revoir ses conditions. 30 % des clients non rentables → revoir la grille de prix. | K32: Citer les clients qui prennent le plus de temps pour le moins de CA. | L32: —
A33: FIN-03 | B33: Finance & Rentabilité | C33: Marges et rentabilité | D33: Coût de revient | E33: Pratique | F33: Qualifié | G33: Calculé | H33: FIN-03.01 | I33: — | J33: Coût inconnu sur l'offre phare → le calculer sur elle seule d'abord. Inconnu sur 20 offres → méthode simple par familles. | K33: Première action : chiffrer une prestation type de bout en bout. | L33: —
A34: FIN-04 | B34: Finance & Rentabilité | C34: Marges et rentabilité | D34: Érosion des marges | E34: Cohérence | F34: Chiffré (marge) | G34: Calculé | H34: FIN-04.01 | I34: Prix (ACQ-13) — partagé, posé une seule fois | J34: Coûts +8 % et prix inchangés → répercussion urgente. Écart d'un point → ajustement à la prochaine révision annuelle. | K34: Comparer les 2 dernières factures du principal fournisseur. | L34: —
A35: FIN-05 | B35: Finance & Rentabilité | C35: Marges et rentabilité | D35: Seuil de rentabilité | E35: Cohérence | F35: Chiffré (marge) | G35: Oui | H35: FIN-05.01, FIN-05.02, FIN-05.03, FIN-05.04, FIN-05.05, FIN-05.06, FIN-05.07 | I35: Partagé avec ACQ-07, ACQ-17 et COM-32 (posé une seule fois) ; CA mensuel (inscription) | J35: CA à 105 % du seuil → sécuriser les charges fixes en priorité. À 150 % → marge de manœuvre pour investir. | K35: Additionner les charges fixes du dernier relevé bancaire. | L35: —
A36: FIN-06 | B36: Finance & Rentabilité | C36: Structure de coûts | D36: Charges fixes et variables | E36: Cohérence | F36: Qualifié | G36: Oui | H36: FIN-06.01, FIN-06.02, FIN-06.03, FIN-06.04 | I36: Partagé avec ACQ-11 et ACQ-21 (posé une seule fois) ; Charges fixes (FIN-05) | J36: 70 % de charges fixes avec une activité saisonnière → transformer des fixes en variables. 30 % → pas prioritaire. | K36: Séparer les dépenses du dernier mois en « tous les mois » et « selon l'activité ». | L36: —
A37: FIN-07 | B37: Finance & Rentabilité | C37: Structure de coûts | D37: Coût de l'équipe | E37: Marché | F37: Chiffré (marge) | G37: Oui | H37: FIN-07.01, FIN-07.02, FIN-07.03, FIN-07.04, FIN-07.05, FIN-07.06, FIN-07.17 | I37: Partagé avec ACQ-13, ACQ-21 et RH-06 (posé une seule fois) ; CA mensuel et effectif (inscription) | J37: Poids élevé et carnet plein → hausse de prix. Poids élevé et carnet vide → renvoi RH (charge) et Acquisition (volume). | K37: Total des salaires et charges du dernier mois. | L37: Seul
A38: FIN-08 | B38: Finance & Rentabilité | C38: Structure de coûts | D38: Achats et sous-traitance | E38: Cohérence | F38: Chiffré (marge) | G38: Oui | H38: FIN-08.01, FIN-08.02, FIN-08.03, FIN-08.04, FIN-08.05, FIN-08.06 | I38: — | J38: Un fournisseur = 60 % des achats → renégocier ou mettre en concurrence. 30 petits fournisseurs → regrouper les achats. | K38: Total des factures fournisseurs du dernier mois. | L38: Sans achats (services purs)
A39: FIN-09 | B39: Finance & Rentabilité | C39: Structure de coûts | D39: Dépenses récurrentes | E39: Pratique | F39: Chiffré (marge) | G39: Oui | H39: FIN-09.01, FIN-09.02, FIN-09.03, FIN-09.10 | I39: — | J39: 5 abonnements → revue en 30 minutes. 40 → inventaire complet sur les relevés. | K39: Lister les prélèvements du dernier relevé bancaire. | L39: —
A40: FIN-10 | B40: Finance & Rentabilité | C40: Structure de coûts | D40: Coût des erreurs | E40: Pratique | F40: Chiffré (marge) | G40: Oui | H40: FIN-10.01, FIN-10.02, FIN-10.03, FIN-10.04, FIN-10.05 | I40: Nombre de reprises partagé avec RH-16 (posé une seule fois) ; pertes de marchandises comptées en FIN-40 | J40: 2 reprises par mois → traiter au cas par cas. 20 → chercher la cause commune (renvoi RH). | K40: Noter les reprises et gestes du mois en cours. | L40: —
A41: FIN-11 | B41: Finance & Rentabilité | C41: Trésorerie | D41: Trésorerie disponible | E41: Pratique | F41: Chiffré (trésorerie) | G41: Oui | H41: FIN-11.01, FIN-11.02, FIN-11.03 | I41: Charges fixes (FIN-05) → nombre de mois couverts calculé | J41: Moins d'un mois couvert → plan de trésorerie semaine par semaine. Plus de 6 mois → réfléchir à l'usage de l'excédent. | K41: Lu sur le compte bancaire. | L41: —
A42: FIN-12 | B42: Finance & Rentabilité | C42: Trésorerie | D42: Flux | E42: Cohérence | F42: Qualifié | G42: Oui | H42: FIN-12.01 | I42: — | J42: Un mois négatif par an → l'anticiper. Un mois sur deux → problème de fond (marges ou délais). | K42: Lu sur les 3 derniers relevés. | L42: —
... A75: FIN-45 | B75: Finance & Rentabilité | C75: Stock (si l'entreprise en a) | D75: Suivi du stock | E75: Pratique | F75: Qualifié | G75: Oui | H75: FIN-45.01, FIN-45.02, FIN-45.03 | I75: — | J75: 50 références → inventaire tournant chaque mois, à la main. 2 000 → logiciel de stock relié à la caisse. | K75: — | L75: Sans stock
A76: FIN-46 | B76: Finance & Rentabilité | C76: Marges et rentabilité | D76: Rémunération du dirigeant | E76: Cohérence | F76: Qualifié | G76: Oui | H76: FIN-46.01, FIN-46.02, FIN-46.03 | I76: — | J76: — | K76: — | L76: — | M76: Nouveau
A77: FIN-47 | B77: Finance & Rentabilité | C77: Pilotage | D77: Cadre de l'activité | E77: Contexte | F77: — | G77: Non | H77: FIN-47.01, FIN-47.02 | I77: — | J77: — | K77: — | L77: — | M77: Nouveau
A78: FIN-48 | B78: Finance & Rentabilité | C78: Financement | D78: Relation avec la banque | E78: Pratique | F78: Qualifié | G78: Non | H78: FIN-48.01 | I78: — | J78: — | K78: — | L78: — | M78: Nouveau
A79: RH-01 | B79: RH & Organisation | C79: Rôles et délégation | D79: Clarté des missions | E79: Pratique | F79: Qualifié | G79: Oui | H79: RH-01.01, RH-01.02 | I79: Effectif (inscription) | J79: 3 personnes → une phrase de mission par personne. 20 → une fiche par fonction. | K79: — | L79: Seul
A80: RH-02 | B80: RH & Organisation | C80: Rôles et délégation | D80: Répartition des responsabilités | E80: Pratique | F80: Qualifié | G80: Oui | H80: RH-02.01, RH-02.02 | I80: Effectif (inscription) | J80: 2 personnes → une liste « qui décide quoi ». 15 → un tableau par domaine. | K80: — | L80: —
A81: RH-03 | B81: RH & Organisation | C81: Rôles et délégation | D81: Autonomie | E81: Cohérence | F81: Qualifié | G81: Oui | H81: RH-03.01, RH-03.02, RH-03.03, RH-03.04, RH-03.05 | I81: Effectif (inscription) | J81: 5 par jour → règles écrites pour les cas fréquents. 40 par jour → déléguer un niveau de décision. | K81: Compter les sollicitations sur une journée type. | L81: Seul
A82: RH-04 | B82: RH & Organisation | C82: Rôles et délégation | D82: Délégation réelle | E82: Cohérence | F82: Qualifié | G82: Oui | H82: RH-04.01, RH-04.02, RH-04.03, RH-04.04, RH-04.05 | I82: — | J82: Peu de tâches confiées → commencer par une tâche récurrente simple. Beaucoup confiées mais reprises → le problème est le suivi, pas la délégation. | K82: — | L82: Seul
...

Sheet Acquisition — données
A1: Code | B1: Thème | C1: Nom du thème | D1: Écran | E1: Donnée | F1: Format de réponse | G1: Mode | H1: Niveau | I1: Condition d'affichage | J1: Période (selon l'ancienneté) | K1: RDV | L1: Commerce | M1: E-commerce | N1: Restaurant | O1: Chantier | P1: B2B | Q1: Abonnement | R1: Location | S1: Sert à | T1: Calcul ou source | U1: Données utilisées | V1: Utilisée dans | W1: Changement du 20 oct. | X1: Métiers concernés
A2: ACQ-01.01 | B2: ACQ-01 | C2: =IFERROR(INDEX(Thèmes!$D$2:$D$190,MATCH(B2,Thèmes!$A$2:$A$190,0)),"") | D2: A01 · Vos types de clients (tableau) | E2: Types de clients (ex. particuliers, professionnels, collectivités), jusqu'à 4 — partagée avec Comm (COM-02.01, COM-09.03) : posée par le premier agent qui en a besoin | F2: Liste | G2: Demandée | H2: Essentiel | I2: — | J2: — | K2: ● | L2: ● | M2: ● | N2: ● | O2: ● | P2: ● | Q2: ● | R2: ● | S2: Parcours | T2: — | U2: — | V2: COM-09.07 | W2: Libellé (« Donnée »)
A3: ACQ-01.02 | B3: ACQ-01 | C3: =IFERROR(INDEX(Thèmes!$D$2:$D$190,MATCH(B3,Thèmes!$A$2:$A$190,0)),"") | D3: A01 · Vos types de clients (tableau) | E3: Part du CA par type de client | F3: % par ligne | G3: Demandée | H3: Essentiel | I3: — | J3: — | K3: ● | L3: ● | M3: ● | N3: ● | O3: ● | P3: ● | Q3: ● | R3: ● | S3: Risque, Levier | T3: — | U3: — | V3: ACQ-01.11
A4: ACQ-01.03 | B4: ACQ-01 | C4: =IFERROR(INDEX(Thèmes!$D$2:$D$190,MATCH(B4,Thèmes!$A$2:$A$190,0)),"") | D4: A01 · Vos types de clients (tableau) | E4: Nombre de clients par type sur 12 mois | F4: Nombre par ligne | G4: Demandée | H4: Essentiel | I4: — | J4: Période adaptée : depuis la création si moins de 12 mois | K4: ● | L4: ● | M4: ● | N4: ● | O4: ● | P4: ● | Q4: ● | R4: ● | S4: Potentiel CA | T4: — | U4: — | V4: ACQ-01.12
A5: ACQ-01.04 | B5: ACQ-01 | C5: =IFERROR(INDEX(Thèmes!$D$2:$D$190,MATCH(B5,Thèmes!$A$2:$A$190,0)),"") | D5: A01 · Vos types de clients (tableau) | E5: Achats par client et par an, par type | F5: Nombre par ligne | G5: Demandée | H5: Approfondi | I5: — | J5: Période adaptée : depuis la création si moins de 12 mois | K5: ● | L5: ● | M5: ● | N5: ● | O5: ● | P5: ● | Q5: ● | R5: ● | S5: Potentiel CA | T5: — | U5: — | V5: ACQ-01.13
A6: ACQ-01.05 | B6: ACQ-01 | C6: =IFERROR(INDEX(Thèmes!$D$2:$D$190,MATCH(B6,Thèmes!$A$2:$A$190,0)),"") | D6: A01 · Vos types de clients (tableau) | E6: Type de client que vous voulez développer en priorité | F6: Choix dans la liste | G6: Demandée | H6: Essentiel | I6: — | J6: — | K6: ● | L6: ● | M6: ● | N6: ● | O6: ● | P6: ● | Q6: ● | R6: ● | S6: Cible | T6: — | U6: — | V6: XA32
A7: ACQ-01.06 | B7: ACQ-01 | C7: =IFERROR(INDEX(Thèmes!$D$2:$D$190,MATCH(B7,Thèmes!$A$2:$A$190,0)),"") | D7: A02 · Votre zone | E7: Répartition des clients par distance : moins de 5 km, 5 à 10, 10 à 25, 25 à 50, plus de 50 km | F7: Tranches en % | G7: Demandée | H7: Essentiel | I7: — | J7: — | K7: ● | L7: ● | N7: ● | O7: ● | P7: ● | Q7: ● | R7: ● | S7: Cible, Levier | T7: — | U7: — | V7: ACQ-01.14, XA31
A8: ACQ-01.07 | B8: ACQ-01 | C8: =IFERROR(INDEX(Thèmes!$D$2:$D$190,MATCH(B8,Thèmes!$A$2:$A$190,0)),"") | D8: A02 · Votre zone | E8: Zone (commune ou quartier) qui génère le plus de CA | F8: Texte | G8: Demandée | H8: Essentiel | I8: — | J8: — | K8: ● | L8: ● | N8: ● | O8: ● | P8: ● | Q8: ● | R8: ● | S8: Levier | T8: — | U8: — | V8: XA31
A9: ACQ-01.08 | B9: ACQ-01 | C9: =IFERROR(INDEX(Thèmes!$D$2:$D$190,MATCH(B9,Thèmes!$A$2:$A$190,0)),"") | D9: A02 · Votre zone | E9: Part du CA faite dans cette zone | F9: % | G9: Demandée | H9: Approfondi | I9: — | J9: — | K9: ● | L9: ● | N9: ● | O9: ● | P9: ● | Q9: ● | R9: ● | S9: Risque, Levier | T9: — | U9: — | V9: XA31
A10: ACQ-01.09 | B10: ACQ-01 | C10: =IFERROR(INDEX(Thèmes!$D$2:$D$190,MATCH(B10,Thèmes!$A$2:$A$190,0)),"") | D10: A02 · Votre zone | E10: Distance maximale acceptée pour une intervention | F10: km | G10: Demandée | H10: Approfondi | I10: — | J10: — | O10: ● | S10: Capacité | T10: — | U10: — | V10: XA31
A11: ACQ-01.10 | B11: ACQ-01 | C11: =IFERROR(INDEX(Thèmes!$D$2:$D$190,MATCH(B11,Thèmes!$A$2:$A$190,0)),"") | D11: A02 · Votre zone | E11: Part des ventes hors de votre région et à l'étranger | F11: % | G11: Demandée | H11: Approfondi | I11: — | J11: — | M11: ● | S11: Opportunité | T11: — | U11: — | V11: Lue par l'IA pour adapter le conseil
A12: ACQ-01.11 | B12: ACQ-01 | C12: =IFERROR(INDEX(Thèmes!$D$2:$D$190,MATCH(B12,Thèmes!$A$2:$A$190,0)),"") | D12: — | E12: CA par type de client | F12: € | G12: Calculée | H12: — | I12: — | J12: — | K12: ● | L12: ● | M12: ● | N12: ● | O12: ● | P12: ● | Q12: ● | R12: ● | S12: Levier | T12: CA mensuel × 12 × part du CA du type | U12: Inscription · CA mensuel, ACQ-01.02 | V12: ACQ-01.12
A13: ACQ-01.12 | B13: ACQ-01 | C13: =IFERROR(INDEX(Thèmes!$D$2:$D$190,MATCH(B13,Thèmes!$A$2:$A$190,0)),"") | D13: — | E13: Valeur annuelle d'un client, par type | F13: € | G13: Calculée | H13: — | I13: — | J13: — | K13: ● | L13: ● | M13: ● | N13: ● | O13: ● | P13: ● | Q13: ● | R13: ● | S13: Levier | T13: CA du type ÷ clients du type | U13: ACQ-01.11, ACQ-01.03 | V13: ACQ-01.13, COM-02.02, XA32
A14: ACQ-01.13 | B14: ACQ-01 | C14: =IFERROR(INDEX(Thèmes!$D$2:$D$190,MATCH(B14,Thèmes!$A$2:$A$190,0)),"") | D14: — | E14: Panier moyen par type | F14: € | G14: Calculée | H14: — | I14: — | J14: — | K14: ● | L14: ● | M14: ● | N14: ● | O14: ● | P14: ● | Q14: ● | R14: ● | S14: Levier | T14: Valeur annuelle d'un client ÷ achats par an | U14: ACQ-01.12, ACQ-01.04 | V14: Affichée dans le rapport
A15: ACQ-01.14 | B15: ACQ-01 | C15: =IFERROR(INDEX(Thèmes!$D$2:$D$190,MATCH(B15,Thèmes!$A$2:$A$190,0)),"") | D15: — | E15: Distance médiane des clients | F15: Tranche de km | G15: Calculée | H15: — | I15: — | J15: — | K15: ● | L15: ● | N15: ● | O15: ● | P15: ● | Q15: ● | R15: ● | S15: Cible | T15: Tranche dans laquelle on atteint 50 % des clients | U15: ACQ-01.06 | V15: XA31
A16: ACQ-01.15 | B16: ACQ-01 | C16: =IFERROR(INDEX(Thèmes!$D$2:$D$190,MATCH(B16,Thèmes!$A$2:$A$190,0)),"") | D16: — | E16: Marge par type de client | F16: % | G16: Autre agent | H16: — | I16: — | J16: — | K16: ● | L16: ● | M16: ● | N16: ● | O16: ● | P16: ● | Q16: ● | R16: ● | S16: Levier | T16: Posée par l'agent Finance (FIN-02) ; lue ici si cet agent est souscrit | U16: FIN-02 | V16: Affichée dans le rapport
A17: ACQ-02.01 | B17: ACQ-02 | C17: =IFERROR(INDEX(Thèmes!$D$2:$D$190,MATCH(B17,Thèmes!$A$2:$A$190,0)),"") | D17: A03 · Vos demandes | E17: Demandes reçues par mois, moyenne des 3 derniers mois (mot adapté au métier : voir onglet Lexique) | F17: Nombre | G17: Demandée | H17: Essentiel | I17: — | J17: Période adaptée : depuis la création si moins de 3 mois | K17: ● | L17: ● | M17: ● | N17: ● | O17: ● | P17: ● | Q17: ● | R17: ● | S17: Parcours, Problème | T17: — | U17: — | V17: ACQ-02.06, ACQ-02.07, ACQ-02.08, ACQ-07.09, ACQ-08.08, ACQ-11.19, ACQ-11.24, ACQ-11.28, COM-13.07, COM-13.08, COM-13.09, XA03, XA38, XA41
A18: ACQ-02.02 | B18: ACQ-02 | C18: =IFERROR(INDEX(Thèmes!$D$2:$D$190,MATCH(B18,Thèmes!$A$2:$A$190,0)),"") | D18: A03 · Vos demandes | E18: Même chiffre il y a 6 mois | F18: Nombre | G18: Demandée | H18: Essentiel | I18: — | J18: 3 mois, 6 mois plus tôt (masquée avant 9 mois d'existence) | K18: ● | L18: ● | M18: ● | N18: ● | O18: ● | P18: ● | Q18: ● | R18: ● | S18: Problème | T18: — | U18: — | V18: ACQ-02.06
A19: ACQ-02.03 | B19: ACQ-02 | C19: =IFERROR(INDEX(Thèmes!$D$2:$D$190,MATCH(B19,Thèmes!$A$2:$A$190,0)),"") | D19: A03 · Vos demandes | E19: Même chiffre il y a 12 mois (même saison) | F19: Nombre | G19: Demandée | H19: Essentiel | I19: — | J19: Mêmes 3 mois, un an plus tôt (masquée avant 15 mois d'existence) | K19: ● | L19: ● | M19: ● | N19: ● | O19: ● | P19: ● | Q19: ● | R19: ● | S19: Problème | T19: — | U19: — | V19: ACQ-02.06
A20: ACQ-02.04 | B20: ACQ-02 | C20: =IFERROR(INDEX(Thèmes!$D$2:$D$190,MATCH(B20,Thèmes!$A$2:$A$190,0)),"") | D20: A03 · Vos demandes | E20: Demandes qualifiées par mois (dans votre zone, votre offre et votre gamme de prix) | F20: Nombre ou % | G20: Demandée | H20: Essentiel | I20: — | J20: — | K20: ● | O20: ● | P20: ● | Q20: ● | S20: Problème, Parcours | T20: — | U20: — | V20: ACQ-02.07, ACQ-11.21
A21: ACQ-02.05 | B21: ACQ-02 | C21: =IFERROR(INDEX(Thèmes!$D$2:$D$190,MATCH(B21,Thèmes!$A$2:$A$190,0)),"") | D21: A03 · Vos demandes | E21: Motif principal des demandes non qualifiées : hors zone, budget trop faible, hors offre, simple curiosité | F21: Choix | G21: Demandée | H21: Approfondi | I21: — | J21: — | K21: ● | O21: ● | P21: ● | Q21: ● | S21: Levier | T21: — | U21: — | V21: DC04
A22: ACQ-02.06 | B22: ACQ-02 | C22: =IFERROR(INDEX(Thèmes!$D$2:$D$190,MATCH(B22,Thèmes!$A$2:$A$190,0)),"") | D22: — | E22: Évolution des demandes sur 6 et 12 mois | F22: % | G22: Calculée | H22: — | I22: — | J22: — | K22: ● | L22: ● | M22: ● | N22: ● | O22: ● | P22: ● | Q22: ● | R22: ● | S22: Problème | T22: (Moyenne par mois des 3 derniers mois − moyenne par mois des mêmes 3 mois, 6 mois ou un an plus tôt) ÷ cette dernière. Non calculée si les deux réponses ne portent pas sur des mois alignés, ou si le périmètre de l'activité a changé entre les deux périodes (ACQ-23.13). | U22: ACQ-02.01, ACQ-02.02, ACQ-02.03, ACQ-23.13 | V22: COM-32.07, XA30, XC07
A23: ACQ-02.07 | B23: ACQ-02 | C23: =IFERROR(INDEX(Thèmes!$D$2:$D$190,MATCH(B23,Thèmes!$A$2:$A$190,0)),"") | D23: — | E23: Part des demandes qualifiées | F23: % | G23: Calculée | H23: — | I23: — | J23: — | K23: ● | O23: ● | P23: ● | Q23: ● | S23: Problème | T23: Demandes qualifiées ÷ demandes reçues | U23: ACQ-02.04, ACQ-02.01 | V23: XA02
A24: ACQ-02.08 | B24: ACQ-02 | C24: =IFERROR(INDEX(Thèmes!$D$2:$D$190,MATCH(B24,Thèmes!$A$2:$A$190,0)),"") | D24: — | E24: Taux demande → rendez-vous | F24: % | G24: Calculée | H24: — | I24: — | J24: — | K24: ● | O24: ● | P24: ● | S24: Parcours | T24: Rendez-vous obtenus ÷ demandes reçues | U24: ACQ-09.01, ACQ-02.01 | V24: XA02
A25: ACQ-02.09 | B25: ACQ-02 | C25: =IFERROR(INDEX(Thèmes!$D$2:$D$190,MATCH(B25,Thèmes!$A$2:$A$190,0)),"") | D25: — | E25: Valeur d'une demande reçue | F25: € | G25: Calculée | H25: — | I25: — | J25: — | K25: ● | L25: ● | M25: ● | N25: ● | O25: ● | P25: ● | Q25: ● | S25: Potentiel CA | T25: Taux de transformation × montant du premier achat (commerce, restaurant, e-commerce : taux de transformation × panier moyen) | U25: ACQ-11.19, ACQ-11.03, ACQ-11.24, ACQ-11.28, ACQ-15.06 | V25: ACQ-08.09, ACQ-22.15, ACQ-22.18, XA01, XA05
A26: ACQ-03.01 | B26: ACQ-03 | C26: =IFERROR(INDEX(Thèmes!$D$2:$D$190,MATCH(B26,Thèmes!$A$2:$A$190,0)),"") | D26: A04 · Vos canaux (tableau) | E26: Canaux qui amènent des clients : bouche-à-oreille, fiche Google, site, réseaux sociaux, publicité, plateformes, partenaires, prospection, passage, salons — partagée avec Comm (COM-12.01) : posée par le premier agent qui en a besoin | F26: Liste (une ligne par canal) | G26: Demandée | H26: Essentiel | I26: — | J26: — | K26: ● | L26: ● | M26: ● | N26: ● | O26: ● | P26: ● | Q26: ● | R26: ● | S26: Parcours | T26: — | U26: — | V26: COM-12.02 | W26: Libellé (« Donnée »)
A27: ACQ-03.02 | B27: ACQ-03 | C27: =IFERROR(INDEX(Thèmes!$D$2:$D$190,MATCH(B27,Thèmes!$A$2:$A$190,0)),"") | D27: A04 · Vos canaux (tableau) | E27: Part des demandes par canal (le nombre par canal est calculé : ACQ-02.01 × part) | F27: Nombre par ligne | G27: Demandée | H27: Essentiel | I27: D03 · une ligne par canal coché | J27: — | K27: ● | L27: ● | M27: ● | N27: ● | O27: ● | P27: ● | Q27: ● | R27: ● | S27: Parcours | T27: — | U27: — | V27: ACQ-03.07, ACQ-03.09, ACQ-03.12, ACQ-06.09, COM-12.02, COM-19.03, COM-22.02 | W27: Libellé (« Donnée »)
A28: ACQ-03.03 | B28: ACQ-03 | C28: =IFERROR(INDEX(Thèmes!$D$2:$D$190,MATCH(B28,Thèmes!$A$2:$A$190,0)),"") | D28: A04 · Vos canaux (tableau) | E28: Part des nouveaux clients par canal (le nombre par canal est calculé avec le total ACQ-11.01 quand il est posé) | F28: Nombre par ligne | G28: Demandée | H28: Essentiel | I28: D03 · une ligne par canal coché | J28: — | K28: ● | L28: ● | M28: ● | N28: ● | O28: ● | P28: ● | Q28: ● | R28: ● | S28: Parcours | T28: — | U28: — | V28: ACQ-03.07, ACQ-03.08, ACQ-03.10, ACQ-18.04, COM-22.02 | W28: Libellé (« Donnée »)
A29: ACQ-03.04 | B29: ACQ-03 | C29: =IFERROR(INDEX(Thèmes!$D$2:$D$190,MATCH(B29,Thèmes!$A$2:$A$190,0)),"") | D29: A04 · Vos canaux (tableau) | E29: Part du CA sur 12 mois, par canal | F29: % par ligne | G29: Demandée | H29: Essentiel | I29: D03 · une ligne par canal coché | J29: Période adaptée : depuis la création si moins de 12 mois | K29: ● | L29: ● | M29: ● | N29: ● | O29: ● | P29: ● | Q29: ● | R29: ● | S29: Levier | T29: — | U29: — | V29: ACQ-03.08, ACQ-03.11, ACQ-07.07, ACQ-07.12, COM-22.03, XA12
A30: ACQ-03.05 | B30: ACQ-03 | C30: =IFERROR(INDEX(Thèmes!$D$2:$D$190,MATCH(B30,Thèmes!$A$2:$A$190,0)),"") | D30: A04 · Vos canaux (tableau) | E30: Dépense fixe par mois, par canal : publicité, abonnement de plateforme (les commissions prélevées sur les ventes sont demandées à part, écran budget) | F30: € par ligne | G30: Demandée | H30: Essentiel | I30: D04 · seulement les canaux payants cochés | J30: Aujourd'hui | K30: ● | L30: ● | M30: ● | N30: ● | O30: ● | P30: ● | Q30: ● | R30: ● | S30: Perte, Levier | T30: — | U30: — | V30: ACQ-03.09, ACQ-03.10, ACQ-03.11, ACQ-07.06, ACQ-07.12, XA11, XA12
A31: ACQ-03.06 | B31: ACQ-03 | C31: =IFERROR(INDEX(Thèmes!$D$2:$D$190,MATCH(B31,Thèmes!$A$2:$A$190,0)),"") | D31: A04 · Vos canaux (tableau) | E31: Tendance de chaque canal sur 12 mois : en hausse, stable, en baisse | F31: Choix par ligne | G31: Demandée | H31: Approfondi | I31: D03 · une ligne par canal coché | J31: 12 mois précédents (masquée avant 24 mois d'existence) | K31: ● | L31: ● | M31: ● | N31: ● | O31: ● | P31: ● | Q31: ● | R31: ● | S31: Problème | T31: — | U31: — | V31: XA30
A32: ACQ-03.07 | B32: ACQ-03 | C32: =IFERROR(INDEX(Thèmes!$D$2:$D$190,MATCH(B32,Thèmes!$A$2:$A$190,0)),"") | D32: — | E32: Taux de transformation par canal | F32: % | G32: Calculée | H32: — | I32: — | J32: — | K32: ● | L32: ● | M32: ● | N32: ● | O32: ● | P32: ● | Q32: ● | R32: ● | S32: Levier | T32: Nouveaux clients du canal ÷ demandes du canal | U32: ACQ-03.03, ACQ-03.02 | V32: Affichée dans le rapport
A33: ACQ-03.08 | B33: ACQ-03 | C33: =IFERROR(INDEX(Thèmes!$D$2:$D$190,MATCH(B33,Thèmes!$A$2:$A$190,0)),"") | D33: — | E33: Panier moyen par canal | F33: € | G33: Calculée | H33: — | I33: — | J33: — | K33: ● | L33: ● | M33: ● | N33: ● | O33: ● | P33: ● | Q33: ● | R33: ● | S33: Levier | T33: CA du canal sur 12 mois ÷ nouveaux clients du canal sur 12 mois | U33: ACQ-03.04, Inscription · CA mensuel, ACQ-03.03 | V33: Affichée dans le rapport
A34: ACQ-03.09 | B34: ACQ-03 | C34: =IFERROR(INDEX(Thèmes!$D$2:$D$190,MATCH(B34,Thèmes!$A$2:$A$190,0)),"") | D34: — | E34: Coût par demande, par canal | F34: € | G34: Calculée | H34: — | I34: — | J34: — | K34: ● | L34: ● | M34: ● | N34: ● | O34: ● | P34: ● | Q34: ● | R34: ● | S34: Levier | T34: (Dépense du canal + commissions du canal) ÷ demandes du canal | U34: ACQ-03.05, ACQ-07.07, ACQ-03.02 | V34: Affichée dans le rapport
A35: ACQ-03.10 | B35: ACQ-03 | C35: =IFERROR(INDEX(Thèmes!$D$2:$D$190,MATCH(B35,Thèmes!$A$2:$A$190,0)),"") | D35: — | E35: Coût d'acquisition d'un client, par canal | F35: € | G35: Calculée | H35: — | I35: — | J35: — | K35: ● | L35: ● | M35: ● | N35: ● | O35: ● | P35: ● | Q35: ● | R35: ● | S35: Perte, Levier | T35: (Dépense du canal + commissions du canal) ÷ nouveaux clients du canal | U35: ACQ-03.05, ACQ-07.07, ACQ-03.03 | V35: XA10, XA11, XA39, XC32
A36: ACQ-03.11 | B36: ACQ-03 | C36: =IFERROR(INDEX(Thèmes!$D$2:$D$190,MATCH(B36,Thèmes!$A$2:$A$190,0)),"") | D36: — | E36: Rendement de chaque canal (CA rapporté pour 1 € dépensé) | F36: Ratio | G36: Calculée | H36: — | I36: — | J36: — | K36: ● | L36: ● | M36: ● | N36: ● | O36: ● | P36: ● | Q36: ● | R36: ● | S36: Levier | T36: CA du canal ÷ (dépense du canal + commissions du canal) | U36: ACQ-03.04, Inscription · CA mensuel, ACQ-03.05, ACQ-07.07 | V36: XA11
A37: ACQ-03.12 | B37: ACQ-03 | C37: =IFERROR(INDEX(Thèmes!$D$2:$D$190,MATCH(B37,Thèmes!$A$2:$A$190,0)),"") | D37: — | E37: Part des demandes venant du 1er canal | F37: % | G37: Calculée | H37: — | I37: — | J37: — | K37: ● | L37: ● | M37: ● | N37: ● | O37: ● | P37: ● | Q37: ● | R37: ● | S37: Risque | T37: Demandes du 1er canal ÷ total des demandes | U37: ACQ-03.02 | V37: XA13
A38: ACQ-04.01 | B38: ACQ-04 | C38: =IFERROR(INDEX(Thèmes!$D$2:$D$190,MATCH(B38,Thèmes!$A$2:$A$190,0)),"") | D38: A05 · Votre prospection | E38: Heures de prospection par semaine | F38: Heures | G38: Demandée | H38: Essentiel | I38: D03 · si « prospection » est cochée | J38: — | K38: ● | O38: ● | P38: ● | Q38: ● | S38: Capacité | T38: — | U38: — | V38: ACQ-04.09
A39: ACQ-04.02 | B39: ACQ-04 | C39: =IFERROR(INDEX(Thèmes!$D$2:$D$190,MATCH(B39,Thèmes!$A$2:$A$190,0)),"") | D39: A05 · Votre prospection | E39: Actions par semaine : appels, emails, messages, visites, salons | F39: Tableau par type d'action | G39: Demandée | H39: Essentiel | I39: D03 · si « prospection » est cochée | J39: — | K39: ● | O39: ● | P39: ● | Q39: ● | S39: Parcours | T39: — | U39: — | V39: ACQ-04.07, ACQ-04.08, ACQ-04.10
A40: ACQ-04.03 | B40: ACQ-04 | C40: =IFERROR(INDEX(Thèmes!$D$2:$D$190,MATCH(B40,Thèmes!$A$2:$A$190,0)),"") | D40: A05 · Votre prospection | E40: Réponses positives obtenues par mois | F40: Nombre | G40: Demandée | H40: Approfondi | I40: D03 · si « prospection » est cochée | J40: — | K40: ● | O40: ● | P40: ● | Q40: ● | S40: Parcours | T40: — | U40: — | V40: ACQ-04.07
...

Sheet Finance — données
A1: Code | B1: Thème | C1: Nom du thème | D1: Écran | E1: Donnée | F1: Format de réponse | G1: Mode | H1: Niveau | I1: Condition d'affichage | J1: Période (selon l'ancienneté) | K1: RDV | L1: Commerce | M1: E-commerce | N1: Restaurant | O1: Chantier | P1: B2B | Q1: Abonnement | R1: Location | S1: Sert à | T1: Calcul ou source | U1: Données utilisées | V1: Utilisée dans | W1: Changement du 20 oct.
A2: FIN-01.01 | B2: FIN-01 | C2: =IFERROR(INDEX(Thèmes!$D$2:$D$190,MATCH(B2,Thèmes!$A$2:$A$190,0)),"") | D2: A14 · Vos prix et remises | E2: Prix de vos 3 offres principales | F2: € (3 lignes) | G2: Partagée | H2: Essentiel | I2: — | J2: — | K2: ● | L2: ● | M2: ● | N2: ● | O2: ● | P2: ● | Q2: ● | R2: ● | S2: Cible | T2: Posée une seule fois, par le premier agent souscrit qui en a besoin (ACQ-13.01), sinon ici | U2: ACQ-13.01 | V2: FIN-01.04, FIN-03.03
A3: FIN-01.02 | B3: FIN-01 | C3: =IFERROR(INDEX(Thèmes!$D$2:$D$190,MATCH(B3,Thèmes!$A$2:$A$190,0)),"") | D3: A14 · Vos prix et remises | E3: Part du CA de chacune de ces offres | F3: % (3 lignes) | G3: Partagée | H3: Essentiel | I3: — | J3: — | K3: ● | L3: ● | M3: ● | N3: ● | O3: ● | P3: ● | Q3: ● | R3: ● | S3: Levier | T3: Posée une seule fois, par le premier agent souscrit qui en a besoin (ACQ-13.02), sinon ici | U3: ACQ-13.02 | V3: FIN-01.06, XF34
A4: FIN-01.03 | B4: FIN-01 | C4: =IFERROR(INDEX(Thèmes!$D$2:$D$190,MATCH(B4,Thèmes!$A$2:$A$190,0)),"") | D4: F06 · Vos marges (tableau par offre) | E4: Coût direct de chacune de ces 3 offres (matières ou marchandises, sous-traitance, temps passé) — mot adapté au métier : voir Lexique | F4: € (3 lignes) | G4: Demandée | H4: Essentiel | I4: — | J4: — | K4: ● | L4: ● | M4: ● | N4: ● | O4: ● | P4: ● | Q4: ● | R4: ● | S4: Levier | T4: — | U4: — | V4: FIN-01.04, FIN-03.02
A5: FIN-01.04 | B5: FIN-01 | C5: =IFERROR(INDEX(Thèmes!$D$2:$D$190,MATCH(B5,Thèmes!$A$2:$A$190,0)),"") | D5: — | E5: Marge par offre, en € et en % | F5: € et % | G5: Calculée | H5: — | I5: — | J5: — | K5: ● | L5: ● | M5: ● | N5: ● | O5: ● | P5: ● | Q5: ● | R5: ● | S5: Levier | T5: Prix − coût direct, puis ÷ prix | U5: ACQ-13.01, FIN-01.03 | V5: FIN-01.05, FIN-01.06, XF34
A6: FIN-01.05 | B6: FIN-01 | C6: =IFERROR(INDEX(Thèmes!$D$2:$D$190,MATCH(B6,Thèmes!$A$2:$A$190,0)),"") | D6: — | E6: Écart de marge entre l'offre la plus et la moins rentable | F6: Points de % | G6: Calculée | H6: — | I6: — | J6: — | K6: ● | L6: ● | M6: ● | N6: ● | O6: ● | P6: ● | Q6: ● | R6: ● | S6: Problème | T6: Marge la plus haute − marge la plus basse | U6: FIN-01.04 | V6: Affichée dans le rapport
A7: FIN-01.06 | B7: FIN-01 | C7: =IFERROR(INDEX(Thèmes!$D$2:$D$190,MATCH(B7,Thèmes!$A$2:$A$190,0)),"") | D7: — | E7: Marge moyenne pondérée par le poids de chaque offre dans le CA | F7: % | G7: Calculée | H7: — | I7: — | J7: — | K7: ● | L7: ● | M7: ● | N7: ● | O7: ● | P7: ● | Q7: ● | R7: ● | S7: Mesure | T7: Somme (marge de l'offre × part du CA de l'offre) | U7: FIN-01.04, ACQ-13.02 | V7: XF34
A8: FIN-02.01 | B8: FIN-02 | C8: =IFERROR(INDEX(Thèmes!$D$2:$D$190,MATCH(B8,Thèmes!$A$2:$A$190,0)),"") | D8: A16 · Vos plus gros clients (tableau) | E8: Temps passé par mois sur chacun de vos 5 plus gros clients (colonne ajoutée au tableau des gros clients) | F8: Heures (5 lignes) | G8: Demandée | H8: Essentiel | I8: D15 · si clients professionnels réguliers | J8: — | P8: ● | Q8: ● | S8: Levier | T8: — | U8: — | V8: FIN-02.02
A9: FIN-02.02 | B9: FIN-02 | C9: =IFERROR(INDEX(Thèmes!$D$2:$D$190,MATCH(B9,Thèmes!$A$2:$A$190,0)),"") | D9: — | E9: Marge réelle de chacun des 5 plus gros clients | F9: € | G9: Calculée | H9: — | I9: — | J9: — | P9: ● | Q9: ● | S9: Levier | T9: CA mensuel du client − heures passées × coût d'une heure de travail | U9: ACQ-16.01, FIN-02.01, FIN-07.12 | V9: FIN-02.03, XF36
A10: FIN-02.03 | B10: FIN-02 | C10: =IFERROR(INDEX(Thèmes!$D$2:$D$190,MATCH(B10,Thèmes!$A$2:$A$190,0)),"") | D10: — | E10: Clients dont la marge réelle est faible ou négative | F10: Liste | G10: Calculée | H10: — | I10: — | J10: — | P10: ● | Q10: ● | S10: Perte | T10: Clients dont la marge réelle est inférieure à la marge moyenne de l'entreprise | U10: FIN-02.02, FIN-06.08 | V10: XF36
A11: FIN-03.01 | B11: FIN-03 | C11: =IFERROR(INDEX(Thèmes!$D$2:$D$190,MATCH(B11,Thèmes!$A$2:$A$190,0)),"") | D11: F06 · Vos marges (tableau par offre) | E11: Connaissez-vous le coût complet de votre offre principale (y compris sa part de loyer, salaires, frais) ? | F11: Oui chiffré / estimation / non | G11: Demandée | H11: Essentiel | I11: — | J11: — | K11: ● | L11: ● | M11: ● | N11: ● | O11: ● | P11: ● | Q11: ● | R11: ● | S11: Problème | T11: — | U11: — | V11: Notée directement (couleur du thème)
A12: FIN-03.02 | B12: FIN-03 | C12: =IFERROR(INDEX(Thèmes!$D$2:$D$190,MATCH(B12,Thèmes!$A$2:$A$190,0)),"") | D12: — | E12: Coût complet de chaque offre | F12: € | G12: Calculée | H12: — | I12: — | J12: — | K12: ● | L12: ● | M12: ● | N12: ● | O12: ● | P12: ● | Q12: ● | R12: ● | S12: Levier | T12: Coût direct + charges fixes mensuelles ÷ ventes du mois | U12: FIN-01.03, FIN-05.08, FIN-06.02 | V12: FIN-03.03, XF35
A13: FIN-03.03 | B13: FIN-03 | C13: =IFERROR(INDEX(Thèmes!$D$2:$D$190,MATCH(B13,Thèmes!$A$2:$A$190,0)),"") | D13: — | E13: Offres vendues sous leur coût complet | F13: Liste | G13: Calculée | H13: — | I13: — | J13: — | K13: ● | L13: ● | M13: ● | N13: ● | O13: ● | P13: ● | Q13: ● | R13: ● | S13: Perte | T13: Offres dont le prix est inférieur au coût complet | U13: ACQ-13.01, FIN-03.02 | V13: XF35
